<sdf version='1.7'>
  <model name='amr_bot'>
    <link name='base_footprint'>
      <inertial>
        <pose>-0.000321 4.7e-05 0.005182 0 -0 0</pose>
        <mass>5.87584</mass>
        <inertia>
          <ixx>0.0276386</ixx>
          <ixy>-5.51861e-05</ixy>
          <ixz>0.000171648</ixz>
          <iyy>0.0409381</iyy>
          <iyz>-5.24302e-05</iyz>
          <izz>0.0548163</izz>
        </inertia>
      </inertial>
      <collision name='base_footprint_fixed_joint_lump__base_link_collision'>
        <pose>0 0 0 0 0 -3.13728</pose>
        <geometry>
          <mesh>
            <scale>1 1 1</scale>
            <uri>model://twowheelbot/meshes/base_link.STL</uri>
          </mesh>
        </geometry>
        <surface>
          <contact>
            <ode/>
          </contact>
          <friction>
            <ode/>
          </friction>
        </surface>
      </collision>
      <collision name='base_footprint_fixed_joint_lump__lf_caster_collision_1'>
        <pose>0.122 0.107 -0.028 -1.5729 0 0</pose>
        <geometry>
          <mesh>
            <scale>1 1 1</scale>
            <uri>model://twowheelbot/meshes/lf_caster.STL</uri>
          </mesh>
        </geometry>
        <surface>
          <contact>
            <ode/>
          </contact>
          <friction>
            <ode>
              <mu>0.001</mu>
              <mu2>0.001</mu2>
            </ode>
          </friction>
        </surface>
      </collision>
      <collision name='base_footprint_fixed_joint_lump__lidar_link_collision_2'>
        <pose>-0.006338 0.001685 0.193 0 -0 1.5164</pose>
        <geometry>
          <mesh>
            <scale>1 1 1</scale>
            <uri>model://twowheelbot/meshes/lidar_link.STL</uri>
          </mesh>
        </geometry>
        <surface>
          <contact>
            <ode/>
          </contact>
          <friction>
            <ode/>
          </friction>
        </surface>
      </collision>
      <collision name='base_footprint_fixed_joint_lump__lr_caster_collision_3'>
        <pose>-0.154 0.107 -0.028 -1.5729 0 0</pose>
        <geometry>
          <mesh>
            <scale>1 1 1</scale>
            <uri>model://twowheelbot/meshes/lr_caster.STL</uri>
          </mesh>
        </geometry>
        <surface>
          <contact>
            <ode/>
          </contact>
          <friction>
            <ode>
              <mu>0.001</mu>
              <mu2>0.001</mu2>
            </ode>
          </friction>
        </surface>
      </collision>
      <collision name='base_footprint_fixed_joint_lump__rf_caster_collision_4'>
        <pose>0.122 -0.107 -0.028 1.5729 -0 0</pose>
        <geometry>
          <mesh>
            <scale>1 1 1</scale>
            <uri>model://twowheelbot/meshes/rf_caster.STL</uri>
          </mesh>
        </geometry>
        <surface>
          <contact>
            <ode/>
          </contact>
          <friction>
            <ode>
              <mu>0.001</mu>
              <mu2>0.001</mu2>
            </ode>
          </friction>
        </surface>
      </collision>
      <collision name='base_footprint_fixed_joint_lump__rr_caster_collision_5'>
        <pose>-0.154 -0.107 -0.028 1.5729 -0 0</pose>
        <geometry>
          <mesh>
            <scale>1 1 1</scale>
            <uri>model://twowheelbot/meshes/rr_caster.STL</uri>
          </mesh>
        </geometry>
        <surface>
          <contact>
            <ode/>
          </contact>
          <friction>
            <ode>
              <mu>0.001</mu>
              <mu2>0.001</mu2>
            </ode>
          </friction>
        </surface>
      </collision>
      <visual name='base_footprint_fixed_joint_lump__base_link_visual'>
        <pose>0 0 0 0 0 -3.13728</pose>
        <geometry>
          <mesh>
            <scale>1 1 1</scale>
            <uri>model://twowheelbot/meshes/base_link.STL</uri>
          </mesh>
        </geometry>
        <material>
          <script>
            <name>Gazebo/Blue</name>
            <uri>file://media/materials/scripts/gazebo.material</uri>
          </script>
        </material>
      </visual>
      <visual name='base_footprint_fixed_joint_lump__lf_caster_visual_1'>
        <pose>0.122 0.107 -0.028 -1.5729 0 0</pose>
        <geometry>
          <mesh>
            <scale>1 1 1</scale>
            <uri>model://twowheelbot/meshes/lf_caster.STL</uri>
          </mesh>
        </geometry>
        <material>
          <script>
            <name>Gazebo/Orange</name>
            <uri>file://media/materials/scripts/gazebo.material</uri>
          </script>
        </material>
      </visual>
      <visual name='base_footprint_fixed_joint_lump__lidar_link_visual_2'>
        <pose>-0.006338 0.001685 0.193 0 -0 1.5164</pose>
        <geometry>
          <mesh>
            <scale>1 1 1</scale>
            <uri>model://twowheelbot/meshes/lidar_link.STL</uri>
          </mesh>
        </geometry>
        <material>
          <script>
            <name>Gazebo/Yellow</name>
            <uri>file://media/materials/scripts/gazebo.material</uri>
          </script>
        </material>
      </visual>
      <visual name='base_footprint_fixed_joint_lump__lr_caster_visual_3'>
        <pose>-0.154 0.107 -0.028 -1.5729 0 0</pose>
        <geometry>
          <mesh>
            <scale>1 1 1</scale>
            <uri>model://twowheelbot/meshes/lr_caster.STL</uri>
          </mesh>
        </geometry>
        <material>
          <script>
            <name>Gazebo/Orange</name>
            <uri>file://media/materials/scripts/gazebo.material</uri>
          </script>
        </material>
      </visual>
      <visual name='base_footprint_fixed_joint_lump__rf_caster_visual_4'>
        <pose>0.122 -0.107 -0.028 1.5729 -0 0</pose>
        <geometry>
          <mesh>
            <scale>1 1 1</scale>
            <uri>model://twowheelbot/meshes/rf_caster.STL</uri>
          </mesh>
        </geometry>
        <material>
          <script>
            <name>Gazebo/Orange</name>
            <uri>file://media/materials/scripts/gazebo.material</uri>
          </script>
        </material>
      </visual>
      <visual name='base_footprint_fixed_joint_lump__rr_caster_visual_5'>
        <pose>-0.154 -0.107 -0.028 1.5729 -0 0</pose>
        <geometry>
          <mesh>
            <scale>1 1 1</scale>
            <uri>model://twowheelbot/meshes/rr_caster.STL</uri>
          </mesh>
        </geometry>
        <material>
          <script>
            <name>Gazebo/Orange</name>
            <uri>file://media/materials/scripts/gazebo.material</uri>
          </script>
        </material>
      </visual>
      <sensor name='laser' type='ray'>
        <visualize>0</visualize>
        <update_rate>10</update_rate>
        <ray>
          <scan>
            <horizontal>
              <samples>360</samples>
              <min_angle>-3.14</min_angle>
              <max_angle>3.14</max_angle>
              <resolution>1</resolution>
            </horizontal>
          </scan>
          <range>
            <min>0.3</min>
            <max>12</max>
          </range>
        </ray>
        <plugin name='laser_controller' filename='libgazebo_ros_ray_sensor.so'>
          <ros>
            <remapping>~/out:=/scan</remapping>
          </ros>
          <output_type>sensor_msgs/LaserScan</output_type>
          <frame_name>lidar_link</frame_name>
        </plugin>
        <pose>-0.006338 0.001685 0.225 0 -0 1.5164</pose>
      </sensor>
    </link>
    <joint name='left_wheel_joint' type='revolute'>
      <pose relative_to='base_footprint'>0 0.234 0.0305 -1.5729 0 0</pose>
      <parent>base_footprint</parent>
      <child>left_wheel</child>
      <axis>
        <xyz>0 0 1</xyz>
        <limit>
          <lower>-1e+16</lower>
          <upper>1e+16</upper>
        </limit>
        <dynamics>
          <spring_reference>0</spring_reference>
          <spring_stiffness>0</spring_stiffness>
        </dynamics>
      </axis>
    </joint>
    <link name='left_wheel'>
      <pose relative_to='left_wheel_joint'>0 0 0 0 -0 0</pose>
      <inertial>
        <pose>0 0 0 0 -0 0</pose>
        <mass>0.408827</mass>
        <inertia>
          <ixx>0.000714802</ixx>
          <ixy>1.37055e-13</ixy>
          <ixz>-6.32708e-14</ixz>
          <iyy>0.000714802</iyy>
          <iyz>-1.37618e-13</iyz>
          <izz>0.00136124</izz>
        </inertia>
      </inertial>
      <collision name='left_wheel_collision'>
        <pose>0 0 0 0 -0 0</pose>
        <geometry>
          <mesh>
            <scale>1 1 1</scale>
            <uri>model://twowheelbot/meshes/left_wheel.STL</uri>
          </mesh>
        </geometry>
        <surface>
          <contact>
            <ode/>
          </contact>
          <friction>
            <ode/>
          </friction>
        </surface>
      </collision>
      <visual name='left_wheel_visual'>
        <pose>0 0 0 0 -0 0</pose>
        <geometry>
          <mesh>
            <scale>1 1 1</scale>
            <uri>model://twowheelbot/meshes/left_wheel.STL</uri>
          </mesh>
        </geometry>
        <material>
          <script>
            <name>Gazebo/Black</name>
            <uri>file://media/materials/scripts/gazebo.material</uri>
          </script>
        </material>
      </visual>
    </link>
    <joint name='right_wheel_joint' type='revolute'>
      <pose relative_to='base_footprint'>0 -0.234 0.0305 1.5729 -0 0</pose>
      <parent>base_footprint</parent>
      <child>right_wheel</child>
      <axis>
        <xyz>0 0 -1</xyz>
        <limit>
          <lower>-1e+16</lower>
          <upper>1e+16</upper>
        </limit>
        <dynamics>
          <spring_reference>0</spring_reference>
          <spring_stiffness>0</spring_stiffness>
        </dynamics>
      </axis>
    </joint>
    <link name='right_wheel'>
      <pose relative_to='right_wheel_joint'>0 0 0 0 -0 0</pose>
      <inertial>
        <pose>0 0 0 0 -0 0</pose>
        <mass>0.408827</mass>
        <inertia>
          <ixx>0.000714802</ixx>
          <ixy>-4.98729e-13</ixy>
          <ixz>-8.55482e-14</ixz>
          <iyy>0.000714802</iyy>
          <iyz>1.25254e-13</iyz>
          <izz>0.00136124</izz>
        </inertia>
      </inertial>
      <collision name='right_wheel_collision'>
        <pose>0 0 0 0 -0 0</pose>
        <geometry>
          <mesh>
            <scale>1 1 1</scale>
            <uri>model://twowheelbot/meshes/right_wheel.STL</uri>
          </mesh>
        </geometry>
        <surface>
          <contact>
            <ode/>
          </contact>
          <friction>
            <ode/>
          </friction>
        </surface>
      </collision>
      <visual name='right_wheel_visual'>
        <pose>0 0 0 0 -0 0</pose>
        <geometry>
          <mesh>
            <scale>1 1 1</scale>
            <uri>model://twowheelbot/meshes/right_wheel.STL</uri>
          </mesh>
        </geometry>
        <material>
          <script>
            <name>Gazebo/Black</name>
            <uri>file://media/materials/scripts/gazebo.material</uri>
          </script>
        </material>
      </visual>
    </link>
  </model>
</sdf>
