<?xml version="1.0"?>
<robot xmlns:xacro="http://www.ros.org/wiki/xacro" >

  <!-- <xacro:arg name="namespace" default=""/> -->

  <link
    name="holder_link">
    <inertial>
      <origin
        xyz="-0.0057444 0.015463 8.228E-09"
        rpy="0 0 0" />
      <mass
        value="0.077176" />
      <inertia
        ixx="1.695E-05"
        ixy="-3.4251E-10"
        ixz="-3.2046E-10"
        iyy="4.0934E-05"
        iyz="-5.3483E-12"
        izz="2.9418E-05" />
    </inertial>
    <visual>
      <origin
        xyz="0 0 0"
        rpy="0 0 0" />
      <geometry>
        <mesh
          filename="package://newurdf/meshes/holder_link.STL" />
      </geometry>
      <material
        name="">
        <color
          rgba="0.79216 0.81961 0.93333 1" />
      </material>
    </visual>
    <collision>
      <origin
        xyz="0 0 0"
        rpy="0 0 0" />
      <geometry>
        <mesh
          filename="package://newurdf/meshes/holder_link.STL" />
      </geometry>
    </collision>
  </link>
  <joint
    name="holder_joint"
    type="prismatic">
    <origin
      xyz="0.3525 0.1325 -0.000999999999999877"
      rpy="1.5707963267949 0 0" />
    <parent
      link="Chassis" />
    <child
      link="holder_link" />
    <axis
      xyz="0 1 0" />
    <limit
      lower="0"
      upper="0"
      effort="0"
      velocity="0" />
  </joint>
  <link
    name="arm_link">
    <inertial>
      <origin
        xyz="-0.17514 -0.01825 5.4748E-11"
        rpy="0 0 0" />
      <mass
        value="0.052491" />
      <inertia
        ixx="2.4451E-06"
        ixy="-5.6047E-16"
        ixz="-9.763E-15"
        iyy="0.00063994"
        iyz="-2.7945E-14"
        izz="0.00064002" />
    </inertial>
    <visual>
      <origin
        xyz="0 0 0"
        rpy="0 0 0" />
      <geometry>
        <mesh
          filename="package://newurdf/meshes/arm_link.STL" />
      </geometry>
      <material
        name="">
        <color
          rgba="1 1 1 1" />
      </material>
    </visual>
    <collision>
      <origin
        xyz="0 0 0"
        rpy="0 0 0" />
      <geometry>
        <mesh
          filename="package://newurdf/meshes/arm_link.STL" />
      </geometry>
    </collision>
  </link>
  <joint
    name="arm_joint"
    type="revolute">
    <origin
      xyz="0 -0.0120631218778426 0"
      rpy="0 -0.324047240218132 0" />
    <parent
      link="holder_link" />
    <child
      link="arm_link" />
    <axis
      xyz="0 1 0" />
    <limit
      lower="0"
      upper="1.5"
      effort="0"
      velocity="0" />
  </joint>
  


</robot>